Workbook
Name _1_Colour: 'PRINT OTHER'!$D$153:$I$153
Name _1_Colour: 'PRINT APPAREL'!#REF!
Name _2_000: EMBROIDERY!$D$51:$CX$51
Name _2_000: TRANSFERS!#REF!
Name _2_000: [1]SCREENPRINT!#REF!
Name A2PRINT: '[2]WORKING SCREENPRINT GRID'!$D$98:$AS$113
Name A2SCREEN: '[2]WORKING SCREENPRINT GRID'!$D$114:$AS$116
Name A3PRINT: '[2]WORKING SCREENPRINT GRID'!$D$76:$AS$91
Name A3SCREEN: '[2]WORKING SCREENPRINT GRID'!$D$92:$AS$94
Name A4PRINT: '[2]WORKING SCREENPRINT GRID'!$D$54:$AS$69
Name A4SCREEN: '[2]WORKING SCREENPRINT GRID'!$D$70:$AS$72
Name A6PRINT: '[2]WORKING SCREENPRINT GRID'!$D$32:$AS$47
Name A6SCREEN: '[2]WORKING SCREENPRINT GRID'!$D$48:$AS$50
Name ADDSCREEB: 'PRINT OTHER'!$U$125:$U$126
Name ADDSCREEB: 'PRINT APPAREL'!$T$66:$T$67
Name ADDSCREEN: EMBROIDERY!#REF!
Name ADDSCREEN: TRANSFERS!#REF!
Name ADDSCREEN: [1]SCREENPRINT!$C$54:$IO$56
Name BREAKCOLOURS: EMBROIDERY!#REF!
Name BREAKCOLOURS: 'PRINT OTHER'!$F$114:$L$114
Name BREAKCOLOURS: TRANSFERS!#REF!
Name BREAKCOLOURS: 'PRINT APPAREL'!$F$55:$K$55
Name BREAKCOLOURS2: EMBROIDERY!#REF!
Name BREAKCOLOURS2: TRANSFERS!#REF!
Name BREAKCOLOURS2: [1]SCREENPRINT!$E$116:$J$116
Name BREAKDOWN: EMBROIDERY!#REF!
Name BREAKDOWN: 'PRINT OTHER'!$E$115:$E$123
Name BREAKDOWN: TRANSFERS!#REF!
Name BREAKDOWN: 'PRINT APPAREL'!$E$56:$E$64
Name BREAKDOWN3LOCATIONS: EMBROIDERY!$F$38:$K$38
Name BREAKDOWN3LOCATIONS: TRANSFERS!#REF!
Name BREAKDOWN3LOCATIONS: [1]SCREENPRINT!#REF!
Name BREAKDOWN3PRICING: EMBROIDERY!$F$39:$K$47
Name BREAKDOWN3PRICING: TRANSFERS!#REF!
Name BREAKDOWN3PRICING: [1]SCREENPRINT!#REF!
Name BREAKDOWNTABLE: EMBROIDERY!#REF!
Name BREAKDOWNTABLE: 'PRINT OTHER'!$F$115:$L$123
Name BREAKDOWNTABLE: TRANSFERS!#REF!
Name BREAKDOWNTABLE: 'PRINT APPAREL'!$F$56:$K$64
Name BREAKDOWNTABLE2: EMBROIDERY!#REF!
Name BREAKDOWNTABLE2: TRANSFERS!#REF!
Name BREAKDOWNTABLE2: [1]SCREENPRINT!$E$117:$J$125
Name BREAKDOWNTABLE3: EMBROIDERY!$C$39:$E$47
Name BREAKDOWNTABLE3: TRANSFERS!#REF!
Name BREAKDOWNTABLE3: [1]SCREENPRINT!#REF!
Name CAPSOPTIONS: EMBROIDERY!$B$76:$B$79
Name CAPSPRICE: EMBROIDERY!$C$76:$C$79
Name COLOURS: '[2]WORKING SCREENPRINT GRID'!$D$31:$AS$31
Name DIGITISINGCOSTS: TRANSFERS!#REF!
Name DIGITISINGCOSTS: EMBROIDERY!$C$69:$EV$71
Name DIGITISINGOPTIONS: TRANSFERS!#REF!
Name DIGITISINGOPTIONS: EMBROIDERY!$B$69:$B$71
Name EMBPRICING: EMBROIDERY!$D$52:$CX$67
Name EMBPRICING: TRANSFERS!#REF!
Name EMBPRICING: [1]SCREENPRINT!#REF!
Name EMBQTY: TRANSFERS!#REF!
Name EMBQTY: EMBROIDERY!$B$52:$B$67
Name EMBROIDERYCOSTS: TRANSFERS!#REF!
Name EMBROIDERYCOSTS: EMBROIDERY!$C$52:$EV$67
Name FILM_TRANSFERA7_105X75mm: TRANSFERS!$C$50:$X$60

Sheet WORKING WHOLESALE GRID
A1: PRINT - APPAREL
D2: A61 COLOURLIGHT | E2: A61 COLOURSTANDARD | F2: A61 COLOUR POLY | G2: A61 COLOURBLOCKER | H2: A61 COLOURWATERBASED | I2: A61 COLOURSPECIALTY | J2: A62 COLOURLIGHT | K2: A62 COLOURSTANDARD | L2: A62 COLOURPOLY | M2: A62 COLOURBLOCKER | N2: A62 COLOURWATERBASED | O2: A63 COLOURLIGHT | P2: A63 COLOURSTANDARD | Q2: A63 COLOURPOLY | R2: A63 COLOURBLOCKER | S2: A63 COLOURWATERBASED | T2: A64 COLOURLIGHT | U2: A64 COLOURSTANDARD | V2: A64 COLOURPOLY | W2: A64 COLOURBLOCKER | X2: A64 COLOURWATERBASED | Y2: A65 COLOURLIGHT | Z2: A65 COLOURSTANDARD | AA2: A65 COLOURPOLY | AB2: A65 COLOURBLOCKER | AC2: A65 COLOURWATERBASED | AD2: A66 COLOURLIGHT | AE2: A66 COLOURSTANDARD | AF2: A66 COLOURPOLY | AG2: A66 COLOURBLOCKER | AH2: A66 COLOURWATERBASED | AI2: A67 COLOURLIGHT | AJ2: A67 COLOURSTANDARD | AK2: A67 COLOURPOLY | AL2: A67 COLOURBLOCKER | AM2: A67 COLOURWATERBASED | AN2: A68 COLOURLIGHT | AO2: A68 COLOURSTANDARD | AP2: A68 COLOURPOLY | AQ2: A68 COLOURBLOCKER | AR2: A68 COLOURWATERBASED | AS2: A69 COLOURLIGHT | AT2: A69 COLOURSTANDARD | AU2: A69 COLOURPOLY | AV2: A69 COLOURBLOCKER | AW2: A69 COLOURWATERBASED | AX2: A610 COLOURLIGHT | AY2: A610 COLOURSTANDARD | AZ2: A610 COLOURPOLY | BA2: A610 COLOURBLOCKER | BB2: A610 COLOURWATERBASED | BC2: A51 COLOURLIGHT | BD2: A51 COLOURSTANDARD | BE2: A51 COLOURPOLY | BF2: A51 COLOURBLOCKER | BG2: ` | BH2: A51 COLOURSPECIALTY | BI2: A52 COLOURSLIGHT | BJ2: A52 COLOURSSTANDARD | BK2: A52 COLOURSPOLY | BL2: A52 COLOURBLOCKER | BM2: A52 COLOURSWATERBASED | BN2: A53 COLOURSLIGHT | BO2: A53 COLOURSSTANDARD | BP2: A53 COLOURSPOLY | BQ2: A53 COLOURBLOCKER | BR2: A53 COLOURSWATERBASED | BS2: A54 COLOURSLIGHT | BT2: A54 COLOURSSTANDARD | BU2: A54 COLOURSPOLY | BV2: A54 COLOURBLOCKER | BW2: A54 COLOURSWATERBASED | BX2: A55 COLOURSLIGHT | BY2: A55 COLOURSSTANDARD | BZ2: A55 COLOURSPOLY | CA2: A55 COLOURBLOCKER | CB2: A55 COLOURSWATERBASED | CC2: A56 COLOURSLIGHT | CD2: A56 COLOURSSTANDARD | CE2: A56 COLOURSPOLY | CF2: A56 COLOURBLOCKER | CG2: A56 COLOURSWATERBASED | CH2: A57 COLOURSLIGHT | CI2: A57 COLOURSSTANDARD | CJ2: A57 COLOURSPOLY | CK2: A557 COLOURBLOCKER | CL2: A57 COLOURSWATERBASED | CM2: A58 COLOURSLIGHT | CN2: A58 COLOURSSTANDARD | CO2: A58 COLOURSPOLY | CP2: A58 COLOURBLOCKER | CQ2: A58 COLOURSWATERBASED | CR2: A59 COLOURSLIGHT | CS2: A59 COLOURSSTANDARD | CT2: A59 COLOURSPOLY | CU2: A59 COLOURBLOCKER | CV2: A59 COLOURSWATERBASED | CW2: A510 COLOURSLIGHT | CX2: A510 COLOURSSTANDARD | CY2: A510 COLOURSPOLY | CZ2: A510 COLOURBLOCKER | DA2: A510 COLOURSWATERBASED | DB2: A4 A41 COLOURLIGHT | DC2: A41 COLOURSTANDARD | DD2: A41 COLOURPOLY | DE2: A41 COLOURBLOCKER | DF2: A41 COLOURWATERBASED | DG2: A41 COLOURSPECIALTY | DH2: A42 COLOURLIGHT | DI2: A42 COLOURSTANDARD | DJ2: A42 COLOURPOLY | DK2: A42 COLOURBLOCKER | DL2: A42 COLOURWATERBASED | DM2: A43 COLOURLIGHT | DN2: A43 COLOURSTANDARD | DO2: A43 COLOURPOLY | DP2: A43 COLOURBLOCKER | DQ2: A43 COLOURWATERBASED | DR2: A44 COLOURLIGHT | DS2: A44 COLOURSTANDARD | DT2: A44 COLOURPOLY | DU2: A44 COLOURBLOCKER | DV2: A44 COLOURWATERBASED | DW2: A45 COLOURLIGHT | DX2: A45 COLOURSTANDARD | DY2: A45 COLOURPOLY | DZ2: A45 COLOURBLOCKER | EA2: A45 COLOURWATERBASED | EB2: A46 COLOURLIGHT | EC2: A46 COLOURSTANDARD | ED2: A46 COLOURPOLY | EE2: A46 COLOURBLOCKER | EF2: A46 COLOURWATERBASED | EG2: A47 COLOURLIGHT | EH2: A47 COLOURSTANDARD | EI2: A47 COLOURPOLY | EJ2: A47 COLOURBLOCKER | EK2: A47 COLOURWATERBASED | EL2: A48 COLOURLIGHT | EM2: A48 COLOURSTANDARD | EN2: A48 COLOURPOLY | EO2: A48 COLOURBLOCKER | EP2: A48 COLOURWATERBASED | EQ2: A49 COLOURLIGHT | ER2: A49 COLOURSTANDARD | ES2: A49 COLOURPOLY | ET2: A49 COLOURBLOCKER | EU2: A49 COLOURWATERBASED | EV2: A410 COLOURLIGHT | EW2: A410 COLOURSTANDARD | EX2: A410 COLOURPOLY | EY2: A410 COLOURBLOCKER | EZ2: A410 COLOURWATERBASED | FA2: A31 COLOURLIGHT | FB2: A31 COLOURSTANDARD | FC2: A31 COLOURPOLY | FD2: A31 COLOURBLOCKER | FE2: A31 COLOURWATERBASED | FF2: A31 COLOURSPECIALTY | FG2: A32 COLOURLIGHT | FH2: A32 COLOURSTANDARD | FI2: A32 COLOURPOLY | FJ2: A32 COLOURBLOCKER | FK2: A32 COLOURWATERBASED | FL2: A33 COLOURLIGHT | FM2: A33 COLOURSTANDARD | FN2: A33 COLOURPOLY | FO2: A33 COLOURBLOCKER | FP2: A33 COLOURWATERBASED | FQ2: A34 COLOURLIGHT | FR2: A34 COLOURSTANDARD | FS2: A34 COLOURPOLY | FT2: A34 COLOURBLOCKER | FU2: A34 COLOURWATERBASED | FV2: A35 COLOURLIGHT | FW2: A35 COLOURSTANDARD | FX2: A35 COLOURPOLY | FY2: A35 COLOURBLOCKER | FZ2: A35 COLOURWATERBASED | GA2: A36 COLOURLIGHT | GB2: A36 COLOURSTANDARD | GC2: A36 COLOURPOLY | GD2: A36 COLOURBLOCKER | GE2: A36 COLOURWATERBASED | GF2: A37 COLOURLIGHT | GG2: A37 COLOURSTANDARD | GH2: A37 COLOURPOLY | GI2: A37 COLOURBLOCKER | GJ2: A37 COLOURWATERBASED | GK2: A38 COLOURLIGHT | GL2: A38 COLOURSTANDARD | GM2: A38 COLOURPOLY | GN2: A38 COLOURBLOCKER | GO2: A38 COLOURWATERBASED | GP2: A39 COLOURLIGHT | GQ2: A39 COLOURSTANDARD | GR2: A39 COLOURPOLY | GS2: A39 COLOURBLOCKER | GT2: A39 COLOURWATERBASED | GU2: A310 COLOURLIGHT | GV2: A310 COLOURSTANDARD | GW2: A310 COLOURPOLY | GX2: A310 COLOURBLOCKER | GY2: A310 COLOURWATERBASED | GZ2: A21 COLOURLIGHT | HA2: A21 COLOURSTANDARD | HB2: A21 COLOURPOLY | HC2: A21 COLOURBLOCKER | HD2: A21 COLOURWATERBASED | HE2: A21 COLOURSPECIALTY | HF2: A22 COLOUR LIGHT | HG2: A22 COLOURSTANDARD | HH2: A22 COLOURPOLY | HI2: A22 COLOURBLOCKER | HJ2: A22 COLOURWATERBASED | HK2: A23 COLOURLIGHT | HL2: A23 COLOURSTANDARD | HM2: A23 COLOURPOLY | HN2: A23COLOURBLOCKER | HO2: A23 COLOURWATERBASED | HP2: A24 COLOURLIGHT | HQ2: A24 COLOURSTANDARD | HR2: A24 COLOURPOLY | HS2: A24 COLOURBLOCKER | HT2: A24 COLOURWATERBASED | HU2: A25 COLOURLIGHT | HV2: A25 COLOURSTANDARD | HW2: A25 COLOURPOLY | HX2: A25 COLOURBLOCKER | HY2: A25 COLOURWATERBASED | HZ2: A26 COLOURLIGHT | IA2: A26 COLOURSTANDARD | IB2: A26 COLOURPOLY | IC2: A26 COLOURBLOCKER | ID2: A26 COLOURWATERBASED | IE2: A27 COLOURLIGHT | IF2: A27 COLOURSTANDARD | IG2: A27 COLOURPOLY | IH2: A27 COLOURBLOCKER | II2: A27 COLOURWATERBASED | IJ2: A28 COLOURLIGHT | IK2: A28 COLOURSTANDARD | IL2: A28 COLOURPOLY | IM2: A28 COLOURBLOCKER | IN2: A28 COLOURWATERBASED | IO2: A29 COLOURLIGHT | IP2: A29 COLOURSTANDARD | IQ2: A29 COLOURPOLY | IR2: A29 COLOURBLOCKER | IS2: A29 COLOURWATERBASED | IT2: A210 COLOURLIGHT | IU2: A210 COLOURSTANDARD | IV2: A210 COLOURPOLY | IW2: A210 COLOURBLOCKER | IX2: A210 COLOURWATERBASED | JB2: A6WB | JC2: A5WB | JD2: A4WB | JE2: A3WB | JF2: A2WB
A3: Quantity breaks | B3: 1 to 4 | D3: 35.06111 | E3: 52.510181 | F3: 70.04694 | G3: 87.693887 | I3: =SUM(D3:G3)/2.5 -> 98.124847 | J3: 52.510181 | K3: 70.04694 | L3: 87.693887 | M3: 105.4398 | O3: 70.04694 | P3: 87.693887 | Q3: 105.4398 | R3: 123.27325 | T3: 87.693887 | U3: 105.4398 | V3: 123.27325 | W3: 141.21704 | Y3: 105.4398 | Z3: 123.27325 | AA3: 141.21704 | AB3: 159.25978 | AD3: 123.27325 | AE3: 141.21704 | AF3: 159.25978 | AG3: 175.21377 | AI3: 141.21704 | AJ3: 159.25978 | AK3: 175.21377 | AL3: 191.24853 | AN3: 159.25978 | AO3: 175.21377 | AP3: 191.24853 | AQ3: 207.36406 | AS3: 175.21377 | AT3: 191.24853 | AU3: 207.36406 | AV3: 223.56036 | AX3: 191.24853 | AY3: 207.36406 | AZ3: 223.56036 | BC3: 36.173659 | BD3: 53.636846 | BE3: 71.195694 | BF3: 88.860914 | BG3: 0 | BH3: =SUM(BC3:BF3)/2.5 -> 99.946845 | BI3: 53.636846 | BJ3: 71.195694 | BK3: 88.860914 | BL3: 106.62521 | BM3: 0 | BN3: 71.195694 | BO3: 88.860914 | BP3: 106.62521 | BQ3: 124.48116 | BR3: 0 | BS3: 88.860914 | BT3: 106.62521 | BU3: 124.48116 | BV3: 142.43956 | BW3: 0 | BX3: 106.62521 | BY3: 124.48116 | BZ3: 142.43956 | CA3: 160.50104 | CB3: 0 | CC3: 124.48116 | CD3: 142.43956 | CE3: 160.50104 | CF3: 176.46021 | CG3: 0 | CH3: 142.43956 | CI3: 160.50104 | CJ3: 176.46021 | CK3: 192.50015 | CL3: 0 | CM3: 160.50104 | CN3: 176.46021 | CO3: 192.50015 | CP3: 208.62086 | CQ3: 0 | CR3: 176.46021 | CS3: 192.50015 | CT3: 208.62086 | CU3: 224.82234 | CV3: 0 | CW3: 192.50015 | CX3: 208.62086 | CY3: 224.82234 | DA3: 0 | DB3: 40.162898 | DC3: 59.575379 | DD3: 79.098325 | DE3: 98.720557 | DG3: =SUM(DB3:DE3)/2.5 -> 111.02286 | DH3: 59.575379 | DI3: 79.098325 | DJ3: 98.720557 | DK3: 118.44208 | DM3: 79.098325 | DN3: 98.720557 | DO3: 118.44208 | DP3: 138.26288 | DR3: 98.720557 | DS3: 118.44208 | DT3: 138.26288 | DU3: 158.17151 | DW3: 118.44208 | DX3: 138.26288 | DY3: 158.17151 | DZ3: 178.19084 | EB3: 138.26288 | EC3: 158.17151 | ED3: 178.19084 | EE3: 196.08272 | EG3: 158.17151 | EH3: 178.19084 | EI3: 196.08272 | EJ3: 214.05536 | EL3: 178.19084 | EM3: 196.08272 | EN3: 214.05536 | EO3: 232.10877 | EQ3: 196.08272 | ER3: 214.05536 | ES3: 232.10877 | ET3: 250.24295 | EV3: 214.05536 | EW3: 232.10877 | EX3: 250.24295 | FA3: 48.321804 | FB3: 72.474736 | FC3: 96.762841 | FD3: 121.17414 | FF3: =SUM(FA3:FD3)/2.5 -> 135.49341 | FG3: 72.474736 | FH3: 96.762841 | FI3: 121.17414 | FJ3: 145.70864 | FL3: 96.762841 | FM3: 121.17414 | FN3: 145.70864 | FO3: 170.35409 | FQ3: 121.17414 | FR3: 145.70864 | FS3: 170.35409 | FT3: 195.13493 | FV3: 145.70864 | FW3: 170.35409 | FX3: 195.13493 | FY3: 220.02662 | GA3: 170.35409 | GB3: 195.13493 | GC3: 220.02662 | GD3: 239.95202 | GF3: 195.13493 | GG3: 220.02662 | GH3: 239.95202 | GI3: 259.95818 | GK3: 220.02662 | GL3: 239.95202 | GM3: 259.95818 | GN3: 280.04511 | GP3: 239.95202 | GQ3: 259.95818 | GR3: 280.04511 | GS3: 300.21282 | GU3: 259.95818 | GV3: 280.04511 | GW3: 300.21282 | GZ3: 82.715472 | HA3: 120.51165 | HB3: 158.55347 | HC3: 196.81777 | HE3: =SUM(GZ3:HC3)/2.5 -> 223.43935 | HF3: 120.51165 | HG3: 158.55347 | HH3: 196.81777 | HI3: 235.30456 | HK3: 158.55347 | HL3: 196.81777 | HM3: 235.30456 | HN3: 274.00159 | HP3: 196.81777 | HQ3: 235.30456 | HR3: 274.00159 | HS3: 312.92182 | HU3: 235.30456 | HV3: 274.00159 | HW3: 312.92182 | HX3: 352.06362 | HZ3: 274.00159 | IA3: 312.92182 | IB3: 352.06362 | IC3: 384.11166 | IE3: 312.92182 | IF3: 352.06362 | IG3: 384.11166 | IH3: 416.32123 | IJ3: 352.06362 | IK3: 384.11166 | IL3: 416.32123 | IM3: 448.69235 | IO3: 384.11166 | IP3: 416.32123 | IQ3: 448.69235 | IR3: 481.225 | IT3: 416.32123 | IU3: 448.69235 | IV3: 481.225 | JB3: N/A | JC3: N/A | JD3: N/A | JE3: N/A | JF3: N/A
B4: 5 to 9 | D4: 14.409261 | E4: 21.208089 | F4: 28.03014 | G4: 34.896555 | I4: =SUM(D4:G4)/2.5 -> 39.417618 | J4: 21.208089 | K4: 28.03014 | L4: 34.896555 | M4: 41.796786 | O4: 28.03014 | P4: 34.896555 | Q4: 41.796786 | R4: 48.720103 | T4: 34.896555 | U4: 41.796786 | V4: 48.720103 | W4: 55.687921 | Y4: 41.796786 | Z4: 48.720103 | AA4: 55.687921 | AB4: 62.689556 | AD4: 48.720103 | AE4: 55.687921 | AF4: 62.689556 | AG4: 69.819057 | AI4: 55.687921 | AJ4: 62.689556 | AK4: 69.819057 | AL4: 76.983173 | AN4: 62.689556 | AO4: 69.819057 | AP4: 76.983173 | AQ4: 84.181905 | AS4: 69.819057 | AT4: 76.983173 | AU4: 84.181905 | AV4: 91.415252 | AX4: 76.983173 | AY4: 84.181905 | AZ4: 91.415252 | BC4: 15.13048 | BD4: 21.941244 | BE4: 28.782724 | BF4: 35.664984 | BG4: 0 | BH4: =SUM(BC4:BF4)/2.5 -> 40.607773 | BI4: 21.941244 | BJ4: 28.782724 | BK4: 35.664984 | BL4: 42.58117 | BM4: 0 | BN4: 28.782724 | BO4: 35.664984 | BP4: 42.58117 | BQ4: 49.524307 | BR4: 0 | BS4: 35.664984 | BT4: 42.58117 | BU4: 49.524307 | BV4: 56.504543 | BW4: 0 | BX4: 42.58117 | BY4: 49.524307 | BZ4: 56.504543 | CA4: 63.52246 | CB4: 0 | CC4: 49.524307 | CD4: 56.504543 | CE4: 63.52246 | CF4: 70.655512 | CG4: 0 | CH4: 56.504543 | CI4: 63.52246 | CJ4: 70.655512 | CK4: 77.82318 | CL4: 0 | CM4: 63.52246 | CN4: 70.655512 | CO4: 77.82318 | CP4: 85.025464 | CQ4: 0 | CR4: 70.655512 | CS4: 77.82318 | CT4: 85.025464 | CU4: 92.262362 | CV4: 0 | CW4: 77.82318 | CX4: 85.025464 | CY4: 92.262362 | DA4: 0 | DB4: 17.431425 | DC4: 25.225895 | DD4: 33.064994 | DE4: 40.938221 | DG4: =SUM(DB4:DE4)/2.5 -> 46.664214 | DH4: 25.225895 | DI4: 33.064994 | DJ4: 40.938221 | DK4: 48.845576 | DM4: 33.064994 | DN4: 40.938221 | DO4: 48.845576 | DP4: 56.78706 | DR4: 40.938221 | DS4: 48.845576 | DT4: 56.78706 | DU4: 64.751894 | DW4: 48.845576 | DX4: 56.78706 | DY4: 64.751894 | DZ4: 72.761588 | EB4: 56.78706 | EC4: 64.751894 | ED4: 72.761588 | EE4: 80.862775 | EG4: 64.751894 | EH4: 72.761588 | EI4: 80.862775 | EJ4: 88.998578 | EL4: 72.761588 | EM4: 80.862775 | EN4: 88.998578 | EO4: 97.168996 | EQ4: 80.862775 | ER4: 88.998578 | ES4: 97.168996 | ET4: 105.37403 | EV4: 88.998578 | EW4: 97.168996 | EX4: 105.37403 | FA4: 26.63296 | FB4: 38.074575 | FC4: 49.588548 | FD4: 61.159877 | FF4: =SUM(FA4:FD4)/2.5 -> 70.182384 | FG4: 38.074575 | FH4: 49.588548 | FI4: 61.159877 | FJ4: 72.788564 | FL4: 49.588548 | FM4: 61.159877 | FN4: 72.788564 | FO4: 84.459278 | FQ4: 61.159877 | FR4: 72.788564 | FS4: 84.459278 | FT4: 96.202613 | FV4: 72.788564 | FW4: 84.459278 | FX4: 96.202613 | FY4: 107.98784 | GA4: 84.459278 | GB4: 96.202613 | GC4: 107.98784 | GD4: 117.16798 | GF4: 96.202613 | GG4: 107.98784 | GH4: 117.16798 | GI4: 126.38274 | GK4: 107.98784 | GL4: 117.16798 | GM4: 126.38274 | GN4: 135.63211 | GP4: 117.16798 | GQ4: 126.38274 | GR4: 135.63211 | GS4: 144.9161 | GU4: 126.38274 | GV4: 135.63211 | GW4: 144.9161 | GZ4: 41.179769 | HA4: 57.53124 | HB4: 73.999696 | HC4: 90.559637 | HE4: =SUM(GZ4:HC4)/2.5 -> 105.30814 | HF4: 57.53124 | HG4: 73.999696 | HH4: 90.559637 | HI4: 107.21106 | HK4: 73.999696 | HL4: 90.559637 | HM4: 107.21106 | HN4: 123.93865 | HP4: 90.559637 | HQ4: 107.21106 | HR4: 123.93865 | HS4: 140.7622 | HU4: 107.21106 | HV4: 123.93865 | HW4: 140.7622 | HX4: 157.67251 | HZ4: 123.93865 | IA4: 140.7622 | IB4: 157.67251 | IC4: 172.06922 | IE4: 140.7622 | IF4: 157.67251 | IG4: 172.06922 | IH4: 186.53517 | IJ4: 157.67251 | IK4: 172.06922 | IL4: 186.53517 | IM4: 201.07034 | IO4: 172.06922 | IP4: 186.53517 | IQ4: 201.07034 | IR4: 215.67475 | IT4: 186.53517 | IU4: 201.07034 | IV4: 215.67475 | JB4: N/A | JC4: N/A | JD4: N/A | JE4: N/A | JF4: N/A
B5: 10 to 14 | D5: 8.968734 | E5: 12.908511 | F5: 16.859548 | G5: 20.84166 | I5: =SUM(D5:G5)/2.5 -> 23.831381 | J5: 12.908511 | K5: 16.859548 | L5: 20.84166 | M5: 24.844961 | O5: 16.859548 | P5: 20.84166 | Q5: 24.844961 | R5: 28.859389 | T5: 20.84166 | U5: 24.844961 | V5: 28.859389 | W5: 32.905025 | Y5: 24.844961 | Z5: 28.859389 | AA5: 32.905025 | AB5: 36.971851 | AD5: 28.859389 | AE5: 32.905025 | AF5: 36.971851 | AG5: 40.834128 | AI5: 32.905025 | AJ5: 36.971851 | AK5: 40.834128 | AL5: 44.715635 | AN5: 36.971851 | AO5: 40.834128 | AP5: 44.715635 | AQ5: 48.616374 | AS5: 40.834128 | AT5: 44.715635 | AU5: 48.616374 | AV5: 52.536343 | AX5: 44.715635 | AY5: 48.616374 | AZ5: 52.536343 | BC5: 9.2223332 | BD5: 13.171468 | BE5: 17.138886 | BF5: 21.134024 | BG5: 0 | BH5: =SUM(BC5:BF5)/2.5 -> 24.266684 | BI5: 13.171468 | BJ5: 17.138886 | BK5: 21.134024 | BL5: 25.150456 | BM5: 0 | BN5: 17.138886 | BO5: 21.134024 | BP5: 25.150456 | BQ5: 29.181641 | BR5: 0 | BS5: 21.134024 | BT5: 25.150456 | BU5: 29.181641 | BV5: 33.237095 | BW5: 0 | BX5: 25.150456 | BY5: 29.181641 | BZ5: 33.237095 | CA5: 37.317364 | CB5: 0 | CC5: 29.181641 | CD5: 33.237095 | CE5: 37.317364 | CF5: 41.181146 | CG5: 0 | CH5: 33.237095 | CI5: 37.317364 | CJ5: 41.181146 | CK5: 45.06416 | CL5: 0 | CM5: 37.317364 | CN5: 41.181146 | CO5: 45.06416 | CP5: 48.966403 | CQ5: 0 | CR5: 41.181146 | CS5: 45.06416 | CT5: 48.966403 | CU5: 52.887878 | CV5: 0 | CW5: 45.06416 | CX5: 48.966403 | CY5: 52.887878 | DA5: 0 | DB5: 10.077919 | DC5: 14.429046 | DD5: 18.811502 | DE5: 23.215447 | DG5: =SUM(DB5:DE5)/2.5 -> 26.613566 | DH5: 14.429046 | DI5: 18.811502 | DJ5: 23.215447 | DK5: 27.64088 | DM5: 18.811502 | DN5: 23.215447 | DO5: 27.64088 | DP5: 32.0878 | DR5: 23.215447 | DS5: 27.64088 | DT5: 32.0878 | DU5: 36.546102 | DW5: 27.64088 | DX5: 32.0878 | DY5: 36.546102 | DZ5: 41.035955 | EB5: 32.0878 | EC5: 36.546102 | ED5: 41.035955 | EE5: 45.287149 | EG5: 36.546102 | EH5: 41.035955 | EI5: 45.287149 | EJ5: 49.557573 | EL5: 41.035955 | EM5: 45.287149 | EN5: 49.557573 | EO5: 53.847228 | EQ5: 45.287149 | ER5: 49.557573 | ES5: 53.847228 | ET5: 58.156114 | EV5: 49.557573 | EW5: 53.847228 | EX5: 58.156114 | FA5: 14.855441 | FB5: 21.045622 | FC5: 27.277819 | FD5: 33.543475 | FF5: =SUM(FA5:FD5)/2.5 -> 38.688943 | FG5: 21.045622 | FH5: 27.277819 | FI5: 33.543475 | FJ5: 39.842588 | FL5: 27.277819 | FM5: 33.543475 | FN5: 39.842588 | FO5: 46.16641 | FQ5: 33.543475 | FR5: 39.842588 | FS5: 46.16641 | FT5: 52.532402 | FV5: 39.842588 | FW5: 46.16641 | FX5: 52.532402 | FY5: 58.923025 | GA5: 46.16641 | GB5: 52.532402 | GC5: 58.923025 | GD5: 63.716169 | GF5: 52.532402 | GG5: 58.923025 | GH5: 63.716169 | GI5: 68.528543 | GK5: 58.923025 | GL5: 63.716169 | GM5: 68.528543 | GN5: 73.360148 | GP5: 63.716169 | GQ5: 68.528543 | GR5: 73.360148 | GS5: 78.210983 | GU5: 68.528543 | GV5: 73.360148 | GW5: 78.210983 | GZ5: 23.491052 | HA5: 32.590053 | HB5: 41.762399 | HC5: 50.989691 | HE5: =SUM(GZ5:HC5)/2.5 -> 59.533278 | HF5: 32.590053 | HG5: 41.762399 | HH5: 50.989691 | HI5: 60.27193 | HK5: 41.762399 | HL5: 50.989691 | HM5: 60.27193 | HN5: 69.600365 | HP5: 50.989691 | HQ5: 60.27193 | HR5: 69.600365 | HS5: 78.982351 | HU5: 60.27193 | HV5: 69.600365 | HW5: 78.982351 | HX5: 88.420519 | HZ5: 69.600365 | IA5: 78.982351 | IB5: 88.420519 | IC5: 96.022548 | IE5: 78.982351 | IF5: 88.420519 | IG5: 96.022548 | IH5: 103.66304 | IJ5: 88.420519 | IK5: 96.022548 | IL5: 103.66304 | IM5: 111.34199 | IO5: 96.022548 | IP5: 103.66304 | IQ5: 111.34199 | IR5: 119.0594 | IT5: 103.66304 | IU5: 111.34199 | IV5: 119.0594 | JB5: N/A | JC5: N/A | JD5: N/A | JE5: N/A | JF5: N/A
B6: 15 to 24 | D6: 6.1721482 | E6: 8.6050747 | F6: 11.043716 | G6: 13.506602 | I6: =SUM(D6:G6)/2.5 -> 15.731016 | J6: 8.6050747 | K6: 11.043716 | L6: 13.506602 | M6: 15.984489 | O6: 11.043716 | P6: 13.506602 | Q6: 15.984489 | R6: 18.467963 | T6: 13.506602 | U6: 15.984489 | V6: 18.467963 | W6: 20.97581 | Y6: 15.984489 | Z6: 18.467963 | AA6: 20.97581 | AB6: 23.498658 | AD6: 18.467963 | AE6: 20.97581 | AF6: 23.498658 | AG6: 26.079764 | AI6: 20.97581 | AJ6: 23.498658 | AK6: 26.079764 | AL6: 28.676254 | AN6: 23.498658 | AO6: 26.079764 | AP6: 28.676254 | AQ6: 31.288129 | AS6: 26.079764 | AT6: 28.676254 | AU6: 31.288129 | AV6: 33.915389 | AX6: 28.676254 | AY6: 31.288129 | AZ6: 33.915389 | BC6: 6.3437497 | BD6: 8.7851494 | BE6: 11.238834 | BF6: 13.713629 | BG6: 0 | BH6: =SUM(BC6:BF6)/2.5 -> 16.032545 | BI6: 8.7851494 | BJ6: 11.238834 | BK6: 13.713629 | BL6: 16.203525 | BM6: 0 | BN6: 11.238834 | BO6: 13.713629 | BP6: 16.203525 | BQ6: 18.702403 | BR6: 0 | BS6: 13.713629 | BT6: 16.203525 | BU6: 18.702403 | BV6: 21.219163 | BW6: 0 | BX6: 16.203525 | BY6: 18.702403 | BZ6: 21.219163 | CA6: 23.754319 | CB6: 0 | CC6: 18.702403 | CD6: 21.219163 | CE6: 23.754319 | CF6: 26.336564 | CG6: 0 | CH6: 21.219163 | CI6: 23.754319 | CJ6: 26.336564 | CK6: 28.934193 | CL6: 0 | CM6: 23.754319 | CN6: 26.336564 | CO6: 28.934193 | CP6: 31.547207 | CQ6: 0 | CR6: 26.336564 | CS6: 28.934193 | CT6: 31.547207 | CU6: 34.175606 | CV6: 0 | CW6: 28.934193 | CX6: 31.547207 | CY6: 34.175606 | DA6: 0 | DB6: 6.8547459 | DC6: 9.5041893 | DD6: 12.178121 | DE6: 14.86734 | DG6: =SUM(DB6:DE6)/2.5 -> 17.361758 | DH6: 9.5041893 | DI6: 12.178121 | DJ6: 14.86734 | DK6: 17.571845 | DM6: 12.178121 | DN6: 14.86734 | DO6: 17.571845 | DP6: 20.291636 | DR6: 14.86734 | DS6: 17.571845 | DT6: 20.291636 | DU6: 23.017258 | DW6: 17.571845 | DX6: 20.291636 | DY6: 23.017258 | DZ6: 25.767581 | EB6: 20.291636 | EC6: 23.017258 | ED6: 25.767581 | EE6: 28.544248 | EG6: 23.017258 | EH6: 25.767581 | EI6: 28.544248 | EJ6: 31.3363 | EL6: 25.767581 | EM6: 28.544248 | EN6: 31.3363 | EO6: 34.143736 | EQ6: 28.544248 | ER6: 31.3363 | ES6: 34.143736 | ET6: 36.966558 | EV6: 31.3363 | EW6: 34.143736 | EX6: 36.966558 | FA6: 9.6673605 | FB6: 13.229577 | FC6: 16.821922 | FD6: 20.43603 | FF6: =SUM(FA6:FD6)/2.5 -> 24.061955 | FG6: 13.229577 | FH6: 16.821922 | FI6: 20.43603 | FJ6: 24.071901 | FL6: 16.821922 | FM6: 20.43603 | FN6: 24.071901 | FO6: 27.720978 | FQ6: 20.43603 | FR6: 24.071901 | FS6: 27.720978 | FT6: 31.400337 | FV6: 24.071901 | FW6: 27.720978 | FX6: 31.400337 | FY6: 35.092825 | GA6: 27.720978 | GB6: 31.400337 | GC6: 35.092825 | GD6: 38.096485 | GF6: 31.400337 | GG6: 35.092825 | GH6: 38.096485 | GI6: 41.11553 | GK6: 35.092825 | GL6: 38.096485 | GM6: 41.11553 | GN6: 44.149959 | GP6: 38.096485 | GQ6: 41.11553 | GR6: 44.149959 | GS6: 47.199773 | GU6: 41.11553 | GV6: 44.149959 | GW6: 47.199773 | GZ6: 15.849029 | HA6: 21.387612 | HB6: 26.980812 | HC6: 32.611062 | HE6: =SUM(GZ6:HC6)/2.5 -> 38.731406 | HF6: 21.387612 | HG6: 26.980812 | HH6: 32.611062 | HI6: 38.278361 | HK6: 26.980812 | HL6: 32.611062 | HM6: 38.278361 | HN6: 43.974153 | HP6: 32.611062 | HQ6: 38.278361 | HR6: 43.974153 | HS6: 49.706057 | HU6: 38.278361 | HV6: 43.974153 | HW6: 49.706057 | HX6: 55.475791 | HZ6: 43.974153 | IA6: 49.706057 | IB6: 55.475791 | IC6: 60.583041 | IE6: 49.706057 | IF6: 55.475791 | IG6: 60.583041 | IH6: 65.721061 | IJ6: 55.475791 | IK6: 60.583041 | IL6: 65.721061 | IM6: 70.889849 | IO6: 60.583041 | IP6: 65.721061 | IQ6: 70.889849 | IR6: 76.089407 | IT6: 65.721061 | IU6: 70.889849 | IV6: 76.089407 | JB6: N/A | JC6: N/A | JD6: N/A | JE6: N/A | JF6: N/A
B7: 25 to 49 | D7: 4.274334 | E7: 5.7784726 | F7: 7.2840895 | G7: 8.8086311 | I7: =SUM(D7:G7)/2.5 -> 10.458211 | J7: 5.7784726 | K7: 7.2840895 | L7: 8.8086311 | M7: 10.343394 | O7: 7.2840895 | P7: 8.8086311 | Q7: 10.343394 | R7: 11.879515 | T7: 8.8086311 | U7: 10.343394 | V7: 11.879515 | W7: 13.434681 | Y7: 10.343394 | Z7: 11.879515 | AA7: 13.434681 | AB7: 15.000069 | AD7: 11.879515 | AE7: 13.434681 | AF7: 15.000069 | AG7: 16.722168 | AI7: 13.434681 | AJ7: 15.000069 | AK7: 16.722168 | AL7: 18.455804 | AN7: 15.000069 | AO7: 16.722168 | AP7: 18.455804 | AQ7: 20.20098 | AS7: 16.722168 | AT7: 18.455804 | AU7: 20.20098 | AV7: 21.957693 | AX7: 18.455804 | AY7: 20.20098 | AZ7: 21.957693 | BC7: 4.4382448 | BD7: 5.9503817 | BE7: 7.4701846 | BF7: 9.0059614 | BG7: 0 | BH7: =SUM(BC7:BF7)/2.5 -> 10.745909 | BI7: 5.9503817 | BJ7: 7.4701846 | BK7: 9.0059614 | BL7: 10.552055 | BM7: 0 | BN7: 7.4701846 | BO7: 9.0059614 | BP7: 10.552055 | BQ7: 12.102704 | BR7: 0 | BS7: 9.0059614 | BT7: 10.552055 | BU7: 12.102704 | BV7: 13.66629 | BW7: 0 | BX7: 10.552055 | BY7: 12.102704 | BZ7: 13.66629 | CA7: 15.243295 | CB7: 0 | CC7: 12.102704 | CD7: 13.66629 | CE7: 15.243295 | CF7: 16.966491 | CG7: 0 | CH7: 13.66629 | CI7: 15.243295 | CJ7: 16.966491 | CK7: 18.701226 | CL7: 0 | CM7: 15.243295 | CN7: 16.966491 | CO7: 18.701226 | CP7: 20.447499 | CQ7: 0 | CR7: 16.966491 | CS7: 18.701226 | CT7: 20.447499 | CU7: 22.205311 | CV7: 0 | CW7: 18.701226 | CX7: 20.447499 | CY7: 22.205311 | DA7: 0 | DB7: 4.8388043 | DC7: 6.4619493 | DD7: 8.1042511 | DE7: 9.7570473 | DG7: =SUM(DB7:DE7)/2.5 -> 11.664821 | DH7: 6.4619493 | DI7: 8.1042511 | DJ7: 9.7570473 | DK7: 11.420338 | DM7: 8.1042511 | DN7: 9.7570473 | DO7: 11.420338 | DP7: 13.094122 | DR7: 9.7570473 | DS7: 11.420338 | DT7: 13.094122 | DU7: 14.769497 | DW7: 11.420338 | DX7: 13.094122 | DY7: 14.769497 | DZ7: 16.46423 | EB7: 13.094122 | EC7: 14.769497 | ED7: 16.46423 | EE7: 18.285619 | EG7: 14.769497 | EH7: 16.46423 | EI7: 18.285619 | EJ7: 20.118547 | EL7: 16.46423 | EM7: 18.285619 | EN7: 20.118547 | EO7: 21.963014 | EQ7: 18.285619 | ER7: 20.118547 | ES7: 21.963014 | ET7: 23.819019 | EV7: 20.118547 | EW7: 21.963014 | EX7: 23.819019 | FA7: 7.7329349 | FB7: 10.23866 | FC7: 12.770719 | FD7: 15.320449 | FF7: =SUM(FA7:FD7)/2.5 -> 18.425105 | FG7: 10.23866 | FH7: 12.770719 | FI7: 15.320449 | FJ7: 17.887852 | FL7: 12.770719 | FM7: 15.320449 | FN7: 17.887852 | FO7: 20.464062 | FQ7: 15.320449 | FR7: 17.887852 | FS7: 20.464062 | FT7: 23.066768 | FV7: 17.887852 | FW7: 20.464062 | FX7: 23.066768 | FY7: 25.678201 | GA7: 20.464062 | GB7: 23.066768 | GC7: 25.678201 | GD7: 27.63387 | GF7: 23.066768 | GG7: 25.678201 | GH7: 27.63387 | GI7: 29.601077 | GK7: 25.678201 | GL7: 27.63387 | GM7: 29.601077 | GN7: 31.579822 | GP7: 27.63387 | GQ7: 29.601077 | GR7: 31.579822 | GS7: 33.570106 | GU7: 29.601077 | GV7: 31.579822 | GW7: 33.570106 | GZ7: 12.283278 | HA7: 16.123686 | HB7: 20.009585 | HC7: 23.92365 | HE7: =SUM(GZ7:HC7)/2.5 -> 28.93608 | HF7: 16.123686 | HG7: 20.009585 | HH7: 23.92365 | HI7: 27.865882 | HK7: 20.009585 | HL7: 23.92365 | HM7: 27.865882 | HN7: 31.827415 | HP7: 23.92365 | HQ7: 27.865882 | HR7: 31.827415 | HS7: 35.817034 | HU7: 27.865882 | HV7: 31.827415 | HW7: 35.817034 | HX7: 39.834738 | HZ7: 31.827415 | IA7: 35.817034 | IB7: 39.834738 | IC7: 43.323335 | IE7: 35.817034 | IF7: 39.834738 | IG7: 43.323335 | IH7: 46.835008 | IJ7: 39.834738 | IK7: 43.323335 | IL7: 46.835008 | IM7: 50.369759 | IO7: 43.323335 | IP7: 46.835008 | IQ7: 50.369759 | IR7: 53.927586 | IT7: 46.835008 | IU7: 50.369759 | IV7: 53.927586 | JB7: N/A | JC7: N/A | JD7: N/A | JE7: N/A | JF7: N/A
B8: 50 to 74 | D8: 3.3825833 | E8: 4.4736061 | F8: 5.5644053 | G8: 6.6720211 | H8: =E8+$JB8 -> 5.5505291 | I8: =SUM(D8:G8)/2.5 -> 8.0370463 | J8: 4.4736061 | K8: 5.5644053 | L8: 6.6720211 | M8: 7.7879533 | N8: =K8+$JB8 -> 6.6413284 | O8: 5.5644053 | P8: 6.6720211 | Q8: 7.7879533 | R8: 8.9035422 | S8: =P8+$JB8 -> 7.7489441 | T8: 6.6720211 | U8: 7.7879533 | V8: 8.9035422 | W8: 10.036068 | X8: =U8+$JB8 -> 8.8648764 | Y8: 7.7879533 | Z8: 8.9035422 | AA8: 10.036068 | AB8: 11.176909 | AC8: =Z8+$JB8 -> 9.9804652 | AD8: 8.9035422 | AE8: 10.036068 | AF8: 11.176909 | AG8: 12.341983 | AH8: =AE8+$JB8 -> 11.112991 | AI8: 10.036068 | AJ8: 11.176909 | AK8: 12.341983 | AL8: 13.515518 | AM8: =AJ8+$JB8 -> 12.253832 | AN8: 11.176909 | AO8: 12.341983 | AP8: 13.515518 | AQ8: 14.697514 | AR8: =AO8+$JB8 -> 13.418906 | AS8: 12.341983 | AT8: 13.515518 | AU8: 14.697514 | AV8: 15.887972 | AW8: =AT8+$JB8 -> 14.592441 | AX8: 13.515518 | AY8: 14.697514 | AZ8: 15.887972 | BB8: =AY8+$JB$8 -> 15.774437 | BC8: 3.5108687 | BD8: 4.6095636 | BE8: 5.7140795 | BF8: 6.8325314 | BG8: =BD8+$JC8 -> 6.3018712 | BH8: =SUM(BC8:BF8)/2.5 -> 8.2668172 | BI8: 4.6095636 | BJ8: 5.7140795 | BK8: 6.8325314 | BL8: 7.9593944 | BM8: =BJ8+$JC8 -> 7.4063872 | BN8: 5.7140795 | BO8: 6.8325314 | BP8: 7.9593944 | BQ8: 9.0890394 | BR8: =BO8+$JC8 -> 8.5248391 | BS8: 6.8325314 | BT8: 7.9593944 | BU8: 9.0890394 | BV8: 10.229653 | BW8: =BT8+$JC8 -> 9.6517021 | BX8: 7.9593944 | BY8: 9.0890394 | BZ8: 10.229653 | CA8: 11.381709 | CB8: =BY8+$JC8 -> 10.781347 | CC8: 9.0890394 | CD8: 10.229653 | CE8: 11.381709 | CF8: 12.54772 | CG8: =CD8+$JC8 -> 11.921961 | CH8: 10.229653 | CI8: 11.381709 | CJ8: 12.54772 | CK8: 13.722192 | CL8: =CI8+$JC8 -> 13.074017 | CM8: 11.381709 | CN8: 12.54772 | CO8: 13.722192 | CP8: 14.905126 | CQ8: =CN8+$JC8 -> 14.240028 | CR8: 12.54772 | CS8: 13.722192 | CT8: 14.905126 | CU8: 16.096522 | CV8: =CS8+$JC8 -> 15.4145 | CW8: 13.722192 | CX8: 14.905126 | CY8: 16.096522 | DA8: =CX8+$JC8 -> 16.597434 | DB8: 3.7875744 | DC8: 4.9389791 | DD8: 6.1074304 | DE8: 7.2844682 | DF8: =DC8+$JB8 -> 6.0159022 | DG8: =SUM(DB8:DE8)/2.5 -> 8.8473808 | DH8: 4.9389791 | DI8: 6.1074304 | DJ8: 7.2844682 | DK8: 8.4700925 | DL8: =DI8+$JD8 -> 9.4920458 | DM8: 6.1074304 | DN8: 7.2844682 | DO8: 8.4700925 | DP8: 9.6643034 | DQ8: =DN8+$JD8 -> 10.669084 | DR8: 7.2844682 | DS8: 8.4700925 | DT8: 9.6643034 | DU8: 10.858401 | DV8: =DS8+$JD8 -> 11.854708 | DW8: 8.4700925 | DX8: 9.6643034 | DY8: 10.858401 | DZ8: 12.069745 | EA8: =DX8+$JD8 -> 13.048919 | EB8: 9.6643034 | EC8: 10.858401 | ED8: 12.069745 | EE8: 13.275958 | EF8: =EC8+$JD8 -> 14.243016 | EG8: 10.858401 | EH8: 12.069745 | EI8: 13.275958 | EJ8: 14.490632 | EK8: =EH8+$JD8 -> 15.45436 | EL8: 12.069745 | EM8: 13.275958 | EN8: 14.490632 | EO8: 15.713768 | EP8: =EM8+$JD8 -> 16.660573 | EQ8: 13.275958 | ER8: 14.490632 | ES8: 15.713768 | ET8: 16.945366 | EU8: =ER8+$JD8 -> 17.875248 | EV8: 14.490632 | EW8: 15.713768 | EX8: 16.945366 | EZ8: =EW8+$JD8 -> 19.098384 | FA8: 6.0230384 | FB8: 7.6822246 | FC8: 9.3625966 | FD8: 11.055694 | FE8: =FB8+$JE8 -> 14.451455 | FF8: =SUM(FA8:FD8)/2.5 -> 13.649422 | FG8: 7.6822246 | FH8: 9.3625966 | FI8: 11.055694 | FJ8: 12.761518 | FK8: =FH8+$JE8 -> 16.131827 | FL8: 9.3625966 | FM8: 11.055694 | FN8: 12.761518 | FO8: 14.471407 | FP8: =FM8+$JE8 -> 17.824925 | FQ8: 11.055694 | FR8: 12.761518 | FS8: 14.471407 | FT8: 16.202642 | FU8: =FR8+$JE8 -> 19.530749 | FV8: 12.761518 | FW8: 14.471407 | FX8: 16.202642 | FY8: 17.937863 | FZ8: =FW8+$JE8 -> 21.240638 | GA8: 14.471407 | GB8: 16.202642 | GC8: 17.937863 | GD8: 19.226512 | GE8: =GB8+$JE8 -> 22.971873 | GF8: 16.202642 | GG8: 17.937863 | GH8: 19.226512 | GI8: 20.523623 | GJ8: =GG8+$JE8 -> 24.707094 | GK8: 17.937863 | GL8: 19.226512 | GM8: 20.523623 | GN8: 21.829195 | GO8: =GL8+$JE8 -> 25.995743 | GP8: 19.226512 | GQ8: 20.523623 | GR8: 21.829195 | GS8: 23.143229 | GT8: =GQ8+$JE8 -> 27.292854 | GU8: 20.523623 | GV8: 21.829195 | GW8: 23.143229 | GY8: =GV8+$JE8 -> 28.598426 | GZ8: 9.6759974 | HA8: 12.351973 | HB8: 15.066181 | HC8: 17.801701 | HD8: =HA8+$JF8 -> 20.044281 | HE8: =SUM(GZ8:HC8)/2.5 -> 21.958341 | HF8: 12.351973 | HG8: 15.066181 | HH8: 17.801701 | HI8: 20.558533 | HJ8: =HG8+$JF8 -> 22.758489 | HK8: 15.066181 | HL8: 17.801701 | HM8: 20.558533 | HN8: 23.328018 | HO8: =HL8+$JF8 -> 25.494009 | HP8: 17.801701 | HQ8: 20.558533 | HR8: 23.328018 | HS8: 26.118735 | HT8: =HQ8+$JF8 -> 28.250841 | HU8: 20.558533 | HV8: 23.328018 | HW8: 26.118735 | HX8: 28.930684 | HY8: =HV8+$JF8 -> 31.020326 | HZ8: 23.328018 | IA8: 26.118735 | IB8: 28.930684 | IC8: 31.290931 | ID8: =IA8+$JF8 -> 33.811043 | IE8: 26.118735 | IF8: 28.930684 | IG8: 31.290931 | IH8: 33.668101 | II8: =IF8+$JF8 -> 36.622992 | IJ8: 28.930684 | IK8: 31.290931 | IL8: 33.668101 | IM8: 36.062194 | IN8: =IK8+$JF8 -> 38.983239 | IO8: 31.290931 | IP8: 33.668101 | IQ8: 36.062194 | IR8: 38.473211 | IS8: =IP8+$JF8 -> 41.360409 | IT8: 33.668101 | IU8: 36.062194 | IV8: 38.473211 | IX8: =IU8+$JF8 -> 43.754502 | JB8: 1.0769231 | JC8: 1.6923077 | JD8: 3.3846154 | JE8: 6.7692308 | JF8: 7.6923077
B9: 75 to99 | D9: 2.9350143 | E9: 3.8216713 | F9: 4.7074059 | G9: 5.6088565 | H9: =E9+$JB9 -> 4.7447483 | I9: =SUM(D9:G9)/2.5 -> 6.8291792 | J9: 3.8216713 | K9: 4.7074059 | L9: 5.6088565 | M9: 6.5177236 | N9: =K9+$JB9 -> 5.6304828 | O9: 4.7074059 | P9: 5.6088565 | Q9: 6.5177236 | R9: 7.4255495 | S9: =P9+$JB9 -> 6.5319334 | T9: 5.6088565 | U9: 6.5177236 | V9: 7.4255495 | W9: 8.3492102 | X9: =U9+$JB9 -> 7.4408006 | Y9: 6.5177236 | Z9: 7.4255495 | AA9: 8.3492102 | AB9: 9.2802875 | AC9: =Z9+$JB9 -> 8.3486264 | AD9: 7.4255495 | AE9: 8.3492102 | AF9: 9.2802875 | AG9: 10.248628 | AH9: =AE9+$JB9 -> 9.2722871 | AI9: 8.3492102 | AJ9: 9.2802875 | AK9: 10.248628 | AL9: 11.224661 | AM9: =AJ9+$JB9 -> 10.203364 | AN9: 9.2802875 | AO9: 10.248628 | AP9: 11.224661 | AQ9: 12.208386 | AR9: =AO9+$JB9 -> 11.171705 | AS9: 10.248628 | AT9: 11.224661 | AU9: 12.208386 | AV9: 13.199804 | AW9: =AT9+$JB9 -> 12.147738 | AX9: 11.224661 | AY9: 12.208386 | AZ9: 13.199804 | BB9: =AY9+$JB$8 -> 13.285309 | BC9: 3.057879 | BD9: 3.9520242 | BE9: 4.8511501 | BF9: 5.7631808 | BG9: =BD9+$JC9 -> 5.4904857 | BH9: =SUM(BC9:BF9)/2.5 -> 7.0496936 | BI9: 3.9520242 | BJ9: 4.8511501 | BK9: 5.7631808 | BL9: 6.6827217 | BM9: =BJ9+$JC9 -> 6.3896116 | BN9: 4.8511501 | BO9: 5.7631808 | BP9: 6.6827217 | BQ9: 7.6042752 | BR9: =BO9+$JC9 -> 7.3016423 | BS9: 5.7631808 | BT9: 6.6827217 | BU9: 7.6042752 | BV9: 8.5358365 | BW9: =BT9+$JC9 -> 8.2211832 | BX9: 6.6827217 | BY9: 7.6042752 | BZ9: 8.5358365 | CA9: 9.4778684 | CB9: =BY9+$JC9 -> 9.1427367 | CC9: 7.6042752 | CD9: 8.5358365 | CE9: 9.4778684 | CF9: 10.447126 | CG9: =CD9+$JC9 -> 10.074298 | CH9: 8.5358365 | CI9: 9.4778684 | CJ9: 10.447126 | CK9: 11.424076 | CL9: =CI9+$JC9 -> 11.01633 | CM9: 9.4778684 | CN9: 10.447126 | CO9: 11.424076 | CP9: 12.408718 | CQ9: =CN9+$JC9 -> 11.985587 | CR9: 10.447126 | CS9: 11.424076 | CT9: 12.408718 | CU9: 13.401052 | CV9: =CS9+$JC9 -> 12.962537 | CW9: 11.424076 | CX9: 12.408718 | CY9: 13.401052 | DA9: =CX9+$JC9 -> 13.947179 | DB9: 3.3052869 | DC9: 4.2325695 | DD9: 5.1757959 | DE9: 6.1267062 | DF9: =DC9+$JB9 -> 5.1556464 | DG9: =SUM(DB9:DE9)/2.5 -> 7.5361434 | DH9: 4.2325695 | DI9: 5.1757959 | DJ9: 6.1267062 | DK9: 7.0853006 | DL9: =DI9+$JD9 -> 8.2527189 | DM9: 5.1757959 | DN9: 6.1267062 | DO9: 7.0853006 | DP9: 8.0515789 | DQ9: =DN9+$JD9 -> 9.2036293 | DR9: 6.1267062 | DS9: 7.0853006 | DT9: 8.0515789 | DU9: 9.0170437 | DV9: =DS9+$JD9 -> 10.162224 | DW9: 7.0853006 | DX9: 8.0515789 | DY9: 9.0170437 | DZ9: 9.9986504 | EA9: =DX9+$JD9 -> 11.128502 | EB9: 8.0515789 | EC9: 9.0170437 | ED9: 9.9986504 | EE9: 10.988841 | EF9: =EC9+$JD9 -> 12.093967 | EG9: 9.0170437 | EH9: 9.9986504 | EI9: 10.988841 | EJ9: 11.986725 | EK9: =EH9+$JD9 -> 13.075573 | EL9: 9.9986504 | EM9: 10.988841 | EN9: 11.986725 | EO9: 12.9923 | EP9: =EM9+$JD9 -> 14.065764 | EQ9: 10.988841 | ER9: 11.986725 | ES9: 12.9923 | ET9: 14.005568 | EU9: =ER9+$JD9 -> 15.063648 | EV9: 11.986725 | EW9: 12.9923 | EX9: 14.005568 | EZ9: =EW9+$JD9 -> 16.069223 | FA9: 4.9365294 | FB9: 6.153748 | FC9: 7.389178 | FD9: 8.6348001 | FE9: =FB9+$JE9 -> 12.307594 | FF9: =SUM(FA9:FD9)/2.5 -> 10.845702 | FG9: 6.153748 | FH9: 7.389178 | FI9: 8.6348001 | FJ9: 9.8906145 | FK9: =FH9+$JE9 -> 13.543024 | FL9: 7.389178 | FM9: 8.6348001 | FN9: 9.8906145 | FO9: 11.148409 | FP9: =FM9+$JE9 -> 14.788646 | FQ9: 8.6348001 | FR9: 9.8906145 | FS9: 11.148409 | FT9: 12.42457 | FU9: =FR9+$JE9 -> 16.044461 | FV9: 9.8906145 | FW9: 11.148409 | FX9: 12.42457 | FY9: 13.702634 | FZ9: =FW9+$JE9 -> 17.302256 | GA9: 11.148409 | GB9: 12.42457 | GC9: 13.702634 | GD9: 14.728529 | GE9: =GB9+$JE9 -> 18.578416 | GF9: 12.42457 | GG9: 13.702634 | GH9: 14.728529 | GI9: 15.762117 | GJ9: =GG9+$JE9 -> 19.85648 | GK9: 13.702634 | GL9: 14.728529 | GM9: 15.762117 | GN9: 16.803398 | GO9: =GL9+$JE9 -> 20.882375 | GP9: 14.728529 | GQ9: 15.762117 | GR9: 16.803398 | GS9: 17.85237 | GT9: =GQ9+$JE9 -> 21.915963 | GU9: 15.762117 | GV9: 16.803398 | GW9: 17.85237 | GY9: =GV9+$JE9 -> 22.957244 | GZ9: 8.184124 | HA9: 10.270933 | HB9: 12.391897 | HC9: 14.530737 | HD9: =HA9+$JF9 -> 17.19401 | HE9: =SUM(GZ9:HC9)/2.5 -> 18.151076 | HF9: 10.270933 | HG9: 12.391897 | HH9: 14.530737 | HI9: 16.687454 | HJ9: =HG9+$JF9 -> 19.314974 | HK9: 12.391897 | HL9: 14.530737 | HM9: 16.687454 | HN9: 18.853835 | HO9: =HL9+$JF9 -> 21.453814 | HP9: 14.530737 | HQ9: 16.687454 | HR9: 18.853835 | HS9: 21.037767 | HT9: =HQ9+$JF9 -> 23.61053 | HU9: 16.687454 | HV9: 18.853835 | HW9: 21.037767 | HX9: 23.239746 | HY9: =HV9+$JF9 -> 25.776911 | HZ9: 18.853835 | IA9: 21.037767 | IB9: 23.239746 | IC9: 25.19814 | ID9: =IA9+$JF9 -> 27.960844 | IE9: 21.037767 | IF9: 23.239746 | IG9: 25.19814 | IH9: 27.171919 | II9: =IF9+$JF9 -> 30.162823 | IJ9: 23.239746 | IK9: 25.19814 | IL9: 27.171919 | IM9: 29.161082 | IN9: =IK9+$JF9 -> 32.121217 | IO9: 25.19814 | IP9: 27.171919 | IQ9: 29.161082 | IR9: 31.165631 | IS9: =IP9+$JF9 -> 34.094996 | IT9: 27.171919 | IU9: 29.161082 | IV9: 31.165631 | IX9: =IU9+$JF9 -> 36.084159 | JB9: 0.92307692 | JC9: 1.5384615 | JD9: 3.0769231 | JE9: 6.1538462 | JF9: 6.9230769
B10: 100 to 249 | D10: 2.4673085 | E10: 3.1420665 | F10: 3.8149296 | G10: 4.5023353 | H10: =E10+$JB10 -> 3.9112973 | I10: =SUM(D10:G10)/2.5 -> 5.570656 | J10: 3.1420665 | K10: 3.8149296 | L10: 4.5023353 | M10: 5.1960846 | N10: =K10+$JB10 -> 4.5841603 | O10: 3.8149296 | P10: 4.5023353 | Q10: 5.1960846 | R10: 5.8878213 | S10: =P10+$JB10 -> 5.2715661 | T10: 4.5023353 | U10: 5.1960846 | V10: 5.8878213 | W10: 6.5942183 | X10: =U10+$JB10 -> 5.9653154 | Y10: 5.1960846 | Z10: 5.8878213 | AA10: 6.5942183 | AB10: 7.3069589 | AC10: =Z10+$JB10 -> 6.657052 | AD10: 5.8878213 | AE10: 6.5942183 | AF10: 7.3069589 | AG10: 8.0886371 | AH10: =AE10+$JB10 -> 7.3634491 | AI10: 6.5942183 | AJ10: 7.3069589 | AK10: 8.0886371 | AL10: 8.8772383 | AM10: =AJ10+$JB10 -> 8.0761897 | AN10: 7.3069589 | AO10: 8.0886371 | AP10: 8.8772383 | AQ10: 9.6727626 | AR10: =AO10+$JB10 -> 8.8578678 | AS10: 8.0886371 | AT10: 8.8772383 | AU10: 9.6727626 | AV10: 10.47521 | AW10: =AT10+$JB10 -> 9.6464691 | AX10: 8.8772383 | AY10: 9.6727626 | AZ10: 10.47521 | BB10: =AY10+$JB$8 -> 10.749686 | BC10: 2.584075 | BD10: 3.2715907 | BE10: 3.9630951 | BF10: 4.6664167 | BG10: =BD10+$JC10 -> 4.6562061 | BH10: =SUM(BC10:BF10)/2.5 -> 5.794071 | BI10: 3.2715907 | BJ10: 3.9630951 | BK10: 4.6664167 | BL10: 5.376226 | BM10: =BJ10+$JC10 -> 5.3477105 | BN10: 3.9630951 | BO10: 4.6664167 | BP10: 5.376226 | BQ10: 6.0870914 | BR10: =BO10+$JC10 -> 6.0510321 | BS10: 4.6664167 | BT10: 5.376226 | BU10: 6.0870914 | BV10: 6.8069122 | BW10: =BT10+$JC10 -> 6.7608414 | BX10: 5.376226 | BY10: 6.0870914 | BZ10: 6.8069122 | CA10: 7.5361452 | CB10: =BY10+$JC10 -> 7.4717068 | CC10: 6.0870914 | CD10: 6.8069122 | CE10: 7.5361452 | CF10: 8.3188894 | CG10: =CD10+$JC10 -> 8.1915276 | CH10: 6.8069122 | CI10: 7.5361452 | CJ10: 8.3188894 | CK10: 9.1085566 | CL10: =CI10+$JC10 -> 8.9207606 | CM10: 7.5361452 | CN10: 8.3188894 | CO10: 9.1085566 | CP10: 9.9051469 | CQ10: =CN10+$JC10 -> 9.7035048 | CR10: 8.3188894 | CS10: 9.1085566 | CT10: 9.9051469 | CU10: 10.70866 | CV10: =CS10+$JC10 -> 10.493172 | CW10: 9.1085566 | CX10: 9.9051469 | CY10: 10.70866 | DA10: =CX10+$JC10 -> 11.289762 | DB10: 2.800927 | DC10: 3.5121356 | DD10: 4.2382597 | DE10: 4.9711393 | DF10: =DC10+$JB10 -> 4.2813664 | DG10: =SUM(DB10:DE10)/2.5 -> 6.2089846 | DH10: 3.5121356 | DI10: 4.2382597 | DJ10: 4.9711393 | DK10: 5.7107742 | DL10: =DI10+$JD10 -> 7.0074905 | DM10: 4.2382597 | DN10: 4.9711393 | DO10: 5.7107742 | DP10: 6.4571646 | DQ10: =DN10+$JD10 -> 7.74037 | DR10: 4.9711393 | DS10: 5.7107742 | DT10: 6.4571646 | DU10: 7.201915 | DV10: =DS10+$JD10 -> 8.480005 | DW10: 5.7107742 | DX10: 6.4571646 | DY10: 7.201915 | DZ10: 7.961777 | EA10: =DX10+$JD10 -> 9.2263954 | EB10: 6.4571646 | EC10: 7.201915 | ED10: 7.961777 | EE10: 8.7465009 | EF10: =EC10+$JD10 -> 9.9711458 | EG10: 7.201915 | EH10: 7.961777 | EI10: 8.7465009 | EJ10: 9.5381478 | EK10: =EH10+$JD10 -> 10.731008 | EL10: 7.961777 | EM10: 8.7465009 | EN10: 9.5381478 | EO10: 10.336718 | EP10: =EM10+$JD10 -> 11.515732 | EQ10: 8.7465009 | ER10: 9.5381478 | ES10: 10.336718 | ET10: 11.142211 | EU10: =ER10+$JD10 -> 12.307379 | EV10: 9.5381478 | EW10: 10.336718 | EX10: 11.142211 | EZ10: =EW10+$JD10 -> 13.105949 | FA10: 4.3113587 | FB10: 5.2834257 | FC10: 6.2718656 | FD10: 7.2694785 | FE10: =FB10+$JE10 -> 10.821887 | FF10: =SUM(FA10:FD10)/2.5 -> 9.2544514 | FG10: 5.2834257 | FH10: 6.2718656 | FI10: 7.2694785 | FJ10: 8.2762643 | FK10: =FH10+$JE10 -> 11.810327 | FL10: 6.2718656 | FM10: 7.2694785 | FN10: 8.2762643 | FO10: 9.28485 | FP10: =FM10+$JE10 -> 12.80794 | FQ10: 7.2694785 | FR10: 8.2762643 | FS10: 9.28485 | FT10: 10.309947 | FU10: =FR10+$JE10 -> 13.814726 | FV10: 8.2762643 | FW10: 9.28485 | FX10: 10.309947 | FY10: 11.336775 | FZ10: =FW10+$JE10 -> 14.823312 | GA10: 9.28485 | GB10: 10.309947 | GC10: 11.336775 | GD10: 12.137196 | GE10: =GB10+$JE10 -> 15.848409 | GF10: 10.309947 | GG10: 11.336775 | GH10: 12.137196 | GI10: 12.944541 | GJ10: =GG10+$JE10 -> 16.875236 | GK10: 11.336775 | GL10: 12.137196 | GM10: 12.944541 | GN10: 13.758809 | GO10: =GL10+$JE10 -> 17.675658 | GP10: 12.137196 | GQ10: 12.944541 | GR10: 13.758809 | GS10: 14.579999 | GT10: =GQ10+$JE10 -> 18.483003 | GU10: 12.944541 | GV10: 13.758809 | GW10: 14.579999 | GY10: =GV10+$JE10 -> 19.29727 | GZ10: 7.1122857 | HA10: 8.7955613 | HB10: 10.510125 | HC10: 12.240618 | HD10: =HA10+$JF10 -> 14.949407 | HE10: =SUM(GZ10:HC10)/2.5 -> 15.463436 | HF10: 8.7955613 | HG10: 10.510125 | HH10: 12.240618 | HI10: 13.987039 | HJ10: =HG10+$JF10 -> 16.663972 | HK10: 10.510125 | HL10: 12.240618 | HM10: 13.987039 | HN10: 15.742015 | HO10: =HL10+$JF10 -> 18.394464 | HP10: 12.240618 | HQ10: 13.987039 | HR10: 15.742015 | HS10: 17.511862 | HT10: =HQ10+$JF10 -> 20.140885 | HU10: 13.987039 | HV10: 15.742015 | HW10: 17.511862 | HX10: 19.298552 | HY10: =HV10+$JF10 -> 21.895861 | HZ10: 15.742015 | IA10: 17.511862 | IB10: 19.298552 | IC10: 20.883697 | ID10: =IA10+$JF10 -> 23.665708 | IE10: 17.511862 | IF10: 19.298552 | IG10: 20.883697 | IH10: 22.482689 | II10: =IF10+$JF10 -> 25.452398 | IJ10: 19.298552 | IK10: 20.883697 | IL10: 22.482689 | IM10: 24.095526 | IN10: =IK10+$JF10 -> 27.037543 | IO10: 20.883697 | IP10: 22.482689 | IQ10: 24.095526 | IR10: 25.72221 | IS10: =IP10+$JF10 -> 28.636535 | IT10: 22.482689 | IU10: 24.095526 | IV10: 25.72221 | IX10: =IU10+$JF10 -> 30.249373 | JB10: 0.76923077 | JC10: 1.3846154 | JD10: 2.7692308 | JE10: 5.5384615 | JF10: 6.1538462
B11: 250 to 499 | D11: 2.1655423 | E11: 2.7542058 | F11: 3.3402777 | G11: 3.9399955 | H11: =E11+$JB11 -> 3.4465135 | I11: =SUM(D11:G11)/2.5 -> 4.8800085 | J11: 2.7542058 | K11: 3.3402777 | L11: 3.9399955 | M11: 4.5452598 | N11: =K11+$JB11 -> 4.0325854 | O11: 3.3402777 | P11: 3.9399955 | Q11: 4.5452598 | R11: 5.1478159 | S11: =P11+$JB11 -> 4.6323031 | T11: 3.9399955 | U11: 4.5452598 | V11: 5.1478159 | W11: 5.7641344 | X11: =U11+$JB11 -> 5.2375675 | Y11: 4.5452598 | Z11: 5.1478159 | AA11: 5.7641344 | AB11: 6.3859996 | AC11: =Z11+$JB11 -> 5.8401236 | AD11: 5.1478159 | AE11: 5.7641344 | AF11: 6.3859996 | AG11: 7.078848 | AH11: =AE11+$JB11 -> 6.4564421 | AI11: 5.7641344 | AJ11: 6.3859996 | AK11: 7.078848 | AL11: 7.7778504 | AM11: =AJ11+$JB11 -> 7.0783073 | AN11: 6.3859996 | AO11: 7.078848 | AP11: 7.7778504 | AQ11: 8.4830065 | AR11: =AO11+$JB11 -> 7.7711557 | AS11: 7.078848 | AT11: 7.7778504 | AU11: 8.4830065 | AV11: 9.1943166 | AW11: =AT11+$JB11 -> 8.4701581 | AX11: 7.7778504 | AY11: 8.4830065 | AZ11: 9.1943166 | BB11: =AY11+$JB$8 -> 9.5599296 | BC11: 2.272748 | BD11: 2.8739761 | BE11: 3.4784248 | BF11: 4.0938274 | BG11: =BD11+$JC11 -> 4.1047453 | BH11: =SUM(BC11:BF11)/2.5 -> 5.0875905 | BI11: 2.8739761 | BJ11: 3.4784248 | BK11: 4.0938274 | BL11: 4.7149194 | BM11: =BJ11+$JC11 -> 4.709194 | BN11: 3.4784248 | BO11: 4.0938274 | BP11: 4.7149194 | BQ11: 5.336335 | BR11: =BO11+$JC11 -> 5.3245967 | BS11: 4.0938274 | BT11: 4.7149194 | BU11: 5.336335 | BV11: 5.9658776 | BW11: =BT11+$JC11 -> 5.9456886 | BX11: 4.7149194 | BY11: 5.336335 | BZ11: 5.9658776 | CA11: 6.6039986 | CB11: =BY11+$JC11 -> 6.5671043 | CC11: 5.336335 | CD11: 5.9658776 | CE11: 6.6039986 | CF11: 7.2978634 | CG11: =CD11+$JC11 -> 7.1966468 | CH11: 5.9658776 | CI11: 6.6039986 | CJ11: 7.2978634 | CK11: 7.997882 | CL11: =CI11+$JC11 -> 7.8347678 | CM11: 6.6039986 | CN11: 7.2978634 | CO11: 7.997882 | CP11: 8.7040545 | CQ11: =CN11+$JC11 -> 8.5286326 | CR11: 7.2978634 | CS11: 7.997882 | CT11: 8.7040545 | CU11: 9.4163808 | CV11: =CS11+$JC11 -> 9.2286513 | CW11: 7.997882 | CX11: 8.7040545 | CY11: 9.4163808 | DA11: =CX11+$JC11 -> 9.9348237 | DB11: 2.4718442 | DC11: 3.0964065 | DD11: 3.7349837 | DE11: 4.3795154 | DF11: =DC11+$JB11 -> 3.7887142 | DG11: =SUM(DB11:DE11)/2.5 -> 5.4730999 | DH11: 3.0964065 | DI11: 3.7349837 | DJ11: 4.3795154 | DK11: 5.0300015 | DL11: =DI11+$JD11 -> 6.1965222 | DM11: 3.7349837 | DN11: 4.3795154 | DO11: 5.0300015 | DP11: 5.6864421 | DQ11: =DN11+$JD11 -> 6.8410539 | DR11: 4.3795154 | DS11: 5.0300015 | DT11: 5.6864421 | DU11: 6.3405434 | DV11: =DS11+$JD11 -> 7.49154 | DW11: 5.0300015 | DX11: 5.6864421 | DY11: 6.3405434 | DZ11: 7.0088539 | EA11: =DX11+$JD11 -> 8.1479805 | EB11: 5.6864421 | EC11: 6.3405434 | ED11: 7.0088539 | EE11: 7.7046062 | EF11: =EC11+$JD11 -> 8.8020818 | EG11: 6.3405434 | EH11: 7.0088539 | EI11: 7.7046062 | EJ11: 8.4065122 | EK11: =EH11+$JD11 -> 9.4703924 | EL11: 7.0088539 | EM11: 7.7046062 | EN11: 8.4065122 | EO11: 9.1145722 | EP11: =EM11+$JD11 -> 10.166145 | EQ11: 7.7046062 | ER11: 8.4065122 | ES11: 9.1145722 | ET11: 9.8287859 | EU11: =ER11+$JD11 -> 10.868051 | EV11: 8.4065122 | EW11: 9.1145722 | EX11: 9.8287859 | EZ11: =EW11+$JD11 -> 11.576111 | FA11: 3.8708954 | FB11: 4.7437073 | FC11: 5.6312393 | FD11: 6.527027 | FE11: =FB11+$JE11 -> 9.6667843 | FF11: =SUM(FA11:FD11)/2.5 -> 8.3091476 | FG11: 4.7437073 | FH11: 5.6312393 | FI11: 6.527027 | FJ11: 7.4310703 | FK11: =FH11+$JE11 -> 10.554316 | FL11: 5.6312393 | FM11: 6.527027 | FN11: 7.4310703 | FO11: 8.3367491 | FP11: =FM11+$JE11 -> 11.450104 | FQ11: 6.527027 | FR11: 7.4310703 | FS11: 8.3367491 | FT11: 9.2572726 | FU11: =FR11+$JE11 -> 12.354147 | FV11: 7.4310703 | FW11: 8.3367491 | FX11: 9.2572726 | FY11: 10.179369 | FZ11: =FW11+$JE11 -> 13.259826 | GA11: 8.3367491 | GB11: 9.2572726 | GC11: 10.179369 | GD11: 10.898191 | GE11: =GB11+$JE11 -> 14.18035 | GF11: 9.2572726 | GG11: 10.179369 | GH11: 10.898191 | GI11: 11.623243 | GJ11: =GG11+$JE11 -> 15.102446 | GK11: 10.179369 | GL11: 10.898191 | GM11: 11.623243 | GN11: 12.354527 | GO11: =GL11+$JE11 -> 15.821268 | GP11: 10.898191 | GQ11: 11.623243 | GR11: 12.354527 | GS11: 13.092041 | GT11: =GQ11+$JE11 -> 16.54632 | GU11: 11.623243 | GV11: 12.354527 | GW11: 13.092041 | GY11: =GV11+$JE11 -> 17.277603 | GZ11: 6.3427396 | HA11: 7.8401138 | HB11: 9.3662231 | HC11: 10.906542 | HD11: =HA11+$JF11 -> 13.378575 | HE11: =SUM(GZ11:HC11)/2.5 -> 13.782248 | HF11: 7.8401138 | HG11: 9.3662231 | HH11: 10.906542 | HI11: 12.461072 | HJ11: =HG11+$JF11 -> 14.904685 | HK11: 9.3662231 | HL11: 10.906542 | HM11: 12.461072 | HN11: 14.023191 | HO11: =HL11+$JF11 -> 16.445004 | HP11: 10.906542 | HQ11: 12.461072 | HR11: 14.023191 | HS11: 15.597816 | HT11: =HQ11+$JF11 -> 17.999533 | HU11: 12.461072 | HV11: 14.023191 | HW11: 15.597816 | HX11: 17.188223 | HY11: =HV11+$JF11 -> 19.561653 | HZ11: 14.023191 | IA11: 15.597816 | IB11: 17.188223 | IC11: 18.602797 | ID11: =IA11+$JF11 -> 21.136278 | IE11: 15.597816 | IF11: 17.188223 | IG11: 18.602797 | IH11: 20.029756 | II11: =IF11+$JF11 -> 22.726685 | IJ11: 17.188223 | IK11: 18.602797 | IL11: 20.029756 | IM11: 21.469099 | IN11: =IK11+$JF11 -> 24.141259 | IO11: 18.602797 | IP11: 20.029756 | IQ11: 21.469099 | IR11: 22.920826 | IS11: =IP11+$JF11 -> 25.568217 | IT11: 20.029756 | IU11: 21.469099 | IV11: 22.920826 | IX11: =IU11+$JF11 -> 27.00756 | JB11: 0.69230769 | JC11: 1.2307692 | JD11: 2.4615385 | JE11: 4.9230769 | JF11: 5.5384615
B12: 500 to 749 | D12: 1.993391 | E12: 2.5426862 | F12: 3.089132 | G12: 3.6487669 | H12: =E12+$JB12 -> 3.1580708 | I12: =SUM(D12:G12)/2.5 -> 4.5095904 | J12: 2.5426862 | K12: 3.089132 | L12: 3.6487669 | M12: 4.2135909 | N12: =K12+$JB12 -> 3.7045166 | O12: 3.089132 | P12: 3.6487669 | Q12: 4.2135909 | R12: 4.7754501 | S12: =P12+$JB12 -> 4.2641515 | T12: 3.6487669 | U12: 4.2135909 | V12: 4.7754501 | W12: 5.3506138 | X12: =U12+$JB12 -> 4.8289755 | Y12: 4.2135909 | Z12: 4.7754501 | AA12: 5.3506138 | AB12: 5.9309666 | AC12: =Z12+$JB12 -> 5.3908347 | AD12: 4.7754501 | AE12: 5.3506138 | AF12: 5.9309666 | AG12: 6.5375275 | AH12: =AE12+$JB12 -> 5.9659984 | AI12: 5.3506138 | AJ12: 5.9309666 | AK12: 6.5375275 | AL12: 7.1494731 | AM12: =AJ12+$JB12 -> 6.5463512 | AN12: 5.9309666 | AO12: 6.5375275 | AP12: 7.1494731 | AQ12: 7.7668033 | AR12: =AO12+$JB12 -> 7.1529121 | AS12: 6.5375275 | AT12: 7.1494731 | AU12: 7.7668033 | AV12: 8.3895181 | AW12: =AT12+$JB12 -> 7.7648577 | AX12: 7.1494731 | AY12: 7.7668033 | AZ12: 8.3895181 | BB12: =AY12+$JB$8 -> 8.8437263 | BC12: 2.0888299 | BD12: 2.6504862 | BE12: 3.2150344 | BF12: 3.790113 | BG12: =BD12+$JC12 -> 3.7274093 | BH12: =SUM(BC12:BF12)/2.5 -> 4.6977854 | BI12: 2.6504862 | BJ12: 3.2150344 | BK12: 3.790113 | BL12: 4.3705221 | BM12: =BJ12+$JC12 -> 4.2919575 | BN12: 3.2150344 | BO12: 3.790113 | BP12: 4.3705221 | BQ12: 4.9509616 | BR12: =BO12+$JC12 -> 4.8670361 | BS12: 3.790113 | BT12: 4.3705221 | BU12: 4.9509616 | BV12: 5.5391393 | BW12: =BT12+$JC12 -> 5.4474452 | BX12: 4.3705221 | BY12: 4.9509616 | BZ12: 5.5391393 | CA12: 6.1355012 | CB12: =BY12+$JC12 -> 6.0278847 | CC12: 4.9509616 | CD12: 5.5391393 | CE12: 6.1355012 | CF12: 6.7430179 | CG12: =CD12+$JC12 -> 6.6160623 | CH12: 5.5391393 | CI12: 6.1355012 | CJ12: 6.7430179 | CK12: 7.3559192 | CL12: =CI12+$JC12 -> 7.2124243 | CM12: 6.1355012 | CN12: 6.7430179 | CO12: 7.3559192 | CP12: 7.9742052 | CQ12: =CN12+$JC12 -> 7.819941 | CR12: 6.7430179 | CS12: 7.3559192 | CT12: 7.9742052 | CU12: 8.5978758 | CV12: =CS12+$JC12 -> 8.4328423 | CW12: 7.3559192 | CX12: 7.9742052 | CY12: 8.5978758 | DA12: =CX12+$JC12 -> 9.0511283 | DB12: 2.2660737 | DC12: 2.8506862 | DD12: 3.4488531 | DE12: 4.052613 | DF12: =DC12+$JB12 -> 3.4660708 | DG12: =SUM(DB12:DE12)/2.5 -> 5.0472904 | DH12: 2.8506862 | DI12: 3.4488531 | DJ12: 4.052613 | DK12: 4.6619659 | DL12: =DI12+$JD12 -> 5.6026993 | DM12: 3.4488531 | DN12: 4.052613 | DO12: 4.6619659 | DP12: 5.2769116 | DQ12: =DN12+$JD12 -> 6.2064592 | DR12: 4.052613 | DS12: 4.6619659 | DT12: 5.2769116 | DU12: 5.889258 | DV12: =DS12+$JD12 -> 6.815812 | DW12: 4.6619659 | DX12: 5.2769116 | DY12: 5.889258 | DZ12: 6.5153512 | EA12: =DX12+$JD12 -> 7.4307578 | EB12: 5.2769116 | EC12: 5.889258 | ED12: 6.5153512 | EE12: 7.1246429 | EF12: =EC12+$JD12 -> 8.0431042 | EG12: 5.889258 | EH12: 6.5153512 | EI12: 7.1246429 | EJ12: 7.7393192 | EK12: =EH12+$JD12 -> 8.6691973 | EL12: 6.5153512 | EM12: 7.1246429 | EN12: 7.7393192 | EO12: 8.3593802 | EP12: =EM12+$JD12 -> 9.2784891 | EQ12: 7.1246429 | ER12: 7.7393192 | ES12: 8.3593802 | ET12: 8.9848258 | EU12: =ER12+$JD12 -> 9.8931654 | EV12: 7.7393192 | EW12: 8.3593802 | EX12: 8.9848258 | EZ12: =EW12+$JD12 -> 10.513226 | FA12: 3.4754112 | FB12: 4.2590984 | FC12: 5.0560197 | FD12: 5.8603711 | FE12: =FB12+$JE12 -> 8.5667907 | FF12: =SUM(FA12:FD12)/2.5 -> 7.4603601 | FG12: 4.2590984 | FH12: 5.0560197 | FI12: 5.8603711 | FJ12: 6.6721525 | FK12: =FH12+$JE12 -> 9.363712 | FL12: 5.0560197 | FM12: 5.8603711 | FN12: 6.6721525 | FO12: 7.4854199 | FP12: =FM12+$JE12 -> 10.168063 | FQ12: 5.8603711 | FR12: 6.6721525 | FS12: 7.4854199 | FT12: 8.3120336 | FU12: =FR12+$JE12 -> 10.979845 | FV12: 6.6721525 | FW12: 7.4854199 | FX12: 8.3120336 | FY12: 9.1400771 | FZ12: =FW12+$JE12 -> 11.793112 | GA12: 7.4854199 | GB12: 8.3120336 | GC12: 9.1400771 | GD12: 9.7856146 | GE12: =GB12+$JE12 -> 12.619726 | GF12: 8.3120336 | GG12: 9.1400771 | GH12: 9.7856146 | GI12: 10.43676 | GJ12: =GG12+$JE12 -> 13.447769 | GK12: 9.1400771 | GL12: 9.7856146 | GM12: 10.43676 | GN12: 11.093513 | GO12: =GL12+$JE12 -> 14.093307 | GP12: 9.7856146 | GQ12: 10.43676 | GR12: 11.093513 | GS12: 11.755873 | GT12: =GQ12+$JE12 -> 14.744452 | GU12: 10.43676 | GV12: 11.093513 | GW12: 11.755873 | GY12: =GV12+$JE12 -> 15.401205 | GZ12: 5.7414849 | HA12: 7.1097846 | HB12: 8.5048728 | HC12: 9.9129841 | HD12: =HA12+$JF12 -> 12.032861 | HE12: =SUM(GZ12:HC12)/2.5 -> 12.507651 | HF12: 7.1097846 | HG12: 8.5048728 | HH12: 9.9129841 | HI12: 11.334118 | HJ12: =HG12+$JF12 -> 13.42795 | HK12: 8.5048728 | HL12: 9.9129841 | HM12: 11.334118 | HN12: 12.762332 | HO12: =HL12+$JF12 -> 14.836061 | HP12: 9.9129841 | HQ12: 11.334118 | HR12: 12.762332 | HS12: 14.201292 | HT12: =HQ12+$JF12 -> 16.257195 | HU12: 11.334118 | HV12: 12.762332 | HW12: 14.201292 | HX12: 15.655428 | HY12: =HV12+$JF12 -> 17.685408 | HZ12: 12.762332 | IA12: 14.201292 | IB12: 15.655428 | IC12: 16.910258 | ID12: =IA12+$JF12 -> 19.124369 | IE12: 14.201292 | IF12: 15.655428 | IG12: 16.910258 | IH12: 18.176079 | II12: =IF12+$JF12 -> 20.578505 | IJ12: 15.655428 | IK12: 16.910258 | IL12: 18.176079 | IM12: 19.452893 | IN12: =IK12+$JF12 -> 21.833334 | IO12: 16.910258 | IP12: 18.176079 | IQ12: 19.452893 | IR12: 20.740699 | IS12: =IP12+$JF12 -> 23.099156 | IT12: 18.176079 | IU12: 19.452893 | IV12: 20.740699 | IX12: =IU12+$JF12 -> 24.37597 | JB12: 0.61538462 | JC12: 1.0769231 | JD12: 2.1538462 | JE12: 4.3076923 | JF12: 4.9230769
B13: 750 to 999 | D13: 1.8598131 | E13: 2.3771159 | F13: 2.8914993 | G13: 3.4185631 | H13: =E13+$JB13 -> 2.9155775 | I13: =SUM(D13:G13)/2.5 -> 4.2187966 | J13: 2.3771159 | K13: 2.8914993 | L13: 3.4185631 | M13: 3.9505261 | N13: =K13+$JB13 -> 3.4299608 | O13: 2.8914993 | P13: 3.4185631 | Q13: 3.9505261 | R13: 4.4794572 | S13: =P13+$JB13 -> 3.9570246 | T13: 3.4185631 | U13: 3.9505261 | V13: 4.4794572 | W13: 5.0211812 | X13: =U13+$JB13 -> 4.4889877 | Y13: 3.9505261 | Z13: 4.4794572 | AA13: 5.0211812 | AB13: 5.5678045 | AC13: =Z13+$JB13 -> 5.0179187 | AD13: 4.4794572 | AE13: 5.0211812 | AF13: 5.5678045 | AG13: 6.0888832 | AH13: =AE13+$JB13 -> 5.5596428 | AI13: 5.0211812 | AJ13: 5.5678045 | AK13: 6.0888832 | AL13: 6.6145773 | AM13: =AJ13+$JB13 -> 6.1062661 | AN13: 5.5678045 | AO13: 6.0888832 | AP13: 6.6145773 | AQ13: 7.1448868 | AR13: =AO13+$JB13 -> 6.6273448 | AS13: 6.0888832 | AT13: 6.6145773 | AU13: 7.1448868 | AV13: 7.6798117 | AW13: =AT13+$JB13 -> 7.1530389 | AX13: 6.6145773 | AY13: 7.1448868 | AZ13: 7.6798117 | BB13: =AY13+$JB$8 -> 8.2218099 | BC13: 1.9556904 | BD13: 2.4850322 | BE13: 3.0170391 | BF13: 3.5591409 | BG13: =BD13+$JC13 -> 3.4081091 | BH13: =SUM(BC13:BF13)/2.5 -> 4.406761 | BI13: 2.4850322 | BJ13: 3.0170391 | BK13: 3.5591409 | BL13: 4.1062797 | BM13: =BJ13+$JC13 -> 3.940116 | BN13: 3.0170391 | BO13: 3.5591409 | BP13: 4.1062797 | BQ13: 4.6533003 | BR13: =BO13+$JC13 -> 4.4822178 | BS13: 3.5591409 | BT13: 4.1062797 | BU13: 4.6533003 | BV13: 5.2076998 | BW13: =BT13+$JC13 -> 5.0293566 | BX13: 4.1062797 | BY13: 4.6533003 | BZ13: 5.2076998 | CA13: 5.7699123 | CB13: =BY13+$JC13 -> 5.5763772 | CC13: 4.6533003 | CD13: 5.2076998 | CE13: 5.7699123 | CF13: 6.2919377 | CG13: =CD13+$JC13 -> 6.1307767 | CH13: 5.2076998 | CI13: 5.7699123 | CJ13: 6.2919377 | CK13: 6.8185784 | CL13: =CI13+$JC13 -> 6.6929892 | CM13: 5.7699123 | CN13: 6.2919377 | CO13: 6.8185784 | CP13: 7.3498345 | CQ13: =CN13+$JC13 -> 7.2150146 | CR13: 6.2919377 | CS13: 6.8185784 | CT13: 7.3498345 | CU13: 7.885706 | CV13: =CS13+$JC13 -> 7.7416553 | CW13: 6.8185784 | CX13: 7.3498345 | CY13: 7.885706 | DA13: =CX13+$JC13 -> 8.2729114 | DB13: 2.1337483 | DC13: 2.685448 | DD13: 3.2501844 | DE13: 3.8202139 | DF13: =DC13+$JB13 -> 3.2239095 | DG13: =SUM(DB13:DE13)/2.5 -> 4.7558378 | DH13: 2.685448 | DI13: 3.2501844 | DJ13: 3.8202139 | DK13: 4.3955363 | DL13: =DI13+$JD13 -> 5.0963383 | DM13: 3.2501844 | DN13: 3.8202139 | DO13: 4.3955363 | DP13: 4.9761517 | DQ13: =DN13+$JD13 -> 5.6663677 | DR13: 3.8202139 | DS13: 4.3955363 | DT13: 4.9761517 | DU13: 5.5540914 | DV13: =DS13+$JD13 -> 6.2416902 | DW13: 4.3955363 | DX13: 4.9761517 | DY13: 5.5540914 | DZ13: 6.1452553 | EA13: =DX13+$JD13 -> 6.8223056 | EB13: 4.9761517 | EC13: 5.5540914 | ED13: 6.1452553 | EE13: 6.6690387 | EF13: =EC13+$JD13 -> 7.4002452 | EG13: 5.5540914 | EH13: 6.1452553 | EI13: 6.6690387 | EJ13: 7.1974375 | EK13: =EH13+$JD13 -> 7.9914092 | EL13: 6.1452553 | EM13: 6.6690387 | EN13: 7.1974375 | EO13: 7.7304517 | EP13: =EM13+$JD13 -> 8.5151926 | EQ13: 6.6690387 | ER13: 7.1974375 | ES13: 7.7304517 | ET13: 8.2680812 | EU13: =ER13+$JD13 -> 9.0435913 | EV13: 7.1974375 | EW13: 7.7304517 | EX13: 8.2680812 | EZ13: =EW13+$JD13 -> 9.5766055 | FA13: 3.1203148 | FB13: 3.8239742 | FC13: 4.5395315 | FD13: 5.261776 | FE13: =FB13+$JE13 -> 7.5162818 | FF13: =SUM(FA13:FD13)/2.5 -> 6.6982386 | FG13: 3.8239742 | FH13: 4.5395315 | FI13: 5.261776 | FJ13: 5.9907076 | FK13: =FH13+$JE13 -> 8.2318392 | FL13: 4.5395315 | FM13: 5.261776 | FN13: 5.9907076 | FO13: 6.7209891 | FP13: =FM13+$JE13 -> 8.9540837 | FQ13: 5.261776 | FR13: 5.9907076 | FS13: 6.7209891 | FT13: 7.4632696 | FU13: =FR13+$JE13 -> 9.6830153 | FV13: 5.9907076 | FW13: 6.7209891 | FX13: 7.4632696 | FY13: 8.2068496 | FZ13: =FW13+$JE13 -> 10.413297 | GA13: 6.7209891 | GB13: 7.4632696 | GC13: 8.2068496 | GD13: 8.7865716 | GE13: =GB13+$JE13 -> 11.155577 | GF13: 7.4632696 | GG13: 8.2068496 | GH13: 8.7865716 | GI13: 9.3713406 | GJ13: =GG13+$JE13 -> 11.899157 | GK13: 8.2068496 | GL13: 8.7865716 | GM13: 9.3713406 | GN13: 9.9611566 | GO13: =GL13+$JE13 -> 12.478879 | GP13: 8.7865716 | GQ13: 9.3713406 | GR13: 9.9611566 | GS13: 10.556019 | GT13: =GQ13+$JE13 -> 13.063648 | GU13: 9.3713406 | GV13: 9.9611566 | GW13: 10.556019 | GY13: =GV13+$JE13 -> 13.653464 | GZ13: 5.2540631 | HA13: 6.5094221 | HB13: 7.789716 | HC13: 9.0819899 | HD13: =HA13+$JF13 -> 10.817114 | HE13: =SUM(GZ13:HC13)/2.5 -> 11.454076 | HF13: 6.5094221 | HG13: 7.789716 | HH13: 9.0819899 | HI13: 10.386244 | HJ13: =HG13+$JF13 -> 12.097408 | HK13: 7.789716 | HL13: 9.0819899 | HM13: 10.386244 | HN13: 11.697141 | HO13: =HL13+$JF13 -> 13.389682 | HP13: 9.0819899 | HQ13: 10.386244 | HR13: 11.697141 | HS13: 13.017361 | HT13: =HQ13+$JF13 -> 14.693936 | HU13: 10.386244 | HV13: 11.697141 | HW13: 13.017361 | HX13: 14.352105 | HY13: =HV13+$JF13 -> 16.004833 | HZ13: 11.697141 | IA13: 13.017361 | IB13: 14.352105 | IC13: 15.45561 | ID13: =IA13+$JF13 -> 17.325053 | IE13: 13.017361 | IF13: 14.352105 | IG13: 15.45561 | IH13: 16.568778 | II13: =IF13+$JF13 -> 18.659797 | IJ13: 14.352105 | IK13: 15.45561 | IL13: 16.568778 | IM13: 17.691608 | IN13: =IK13+$JF13 -> 19.763303 | IO13: 15.45561 | IP13: 16.568778 | IQ13: 17.691608 | IR13: 18.824101 | IS13: =IP13+$JF13 -> 20.87647 | IT13: 16.568778 | IU13: 17.691608 | IV13: 18.824101 | IX13: =IU13+$JF13 -> 21.999301 | JB13: 0.53846154 | JC13: 0.92307692 | JD13: 1.8461538 | JE13: 3.6923077 | JF13: 4.3076923
